Workbook

Sheet Read Me
B2: UNO — 5-Year Financial Model
B3: Bottom-up operating model for a rental brokerage launching in Uyo, Akwa Ibom.
B5: HOW TO USE THIS MODEL
B6: Every input lives on the Assumptions tab. Nothing is hardcoded anywhere else. Change a number there and the whole model — monthly engine, annual summary, the figures you would put in a deck — recalculates. Do not type numbers into the Monthly Model or Summary tabs; they are all formulas.
B8: COLOUR CODE
B9: Blue text — an input you edit.
B10: Black text — calculated. Do not overwrite.
B11: Green text — pulled from another tab.
B12: Yellow fill — key assumption. These are placeholders. Replace them with real Uyo numbers before you show this to anyone.
B14: THE NINE NUMBERS THAT MATTER MOST
B15: Everything else is detail. If these nine are wrong, the model is wrong:
B16: 1. Average annual rent by segment, and the mix of deals across segments (Assumptions, rows 9–12)
... B35: This is a model, not a forecast. Its job is to show you which levers matter and what breaks first — not to predict Year 5 revenue. Treat Months 1–18 as the part that has to be defensible and everything after as a shape, not a promise.

Sheet Assumptions
A1: UNO — Model Assumptions
A2: Blue = edit me. Yellow = placeholder, replace with real Uyo data. Column F explains where each number should come from.
A7: MARKET & PRICING — UYO
A8: Segment | B8: Avg annual rent (₦) | C8: % of deals
A9: Self-contain | B9: 350000 | C9: 0.3 | F9: PLACEHOLDER. Walk Ewet Housing, Ikpa Road and Shelter Afrique and price these yourself.
A10: Mini flat | B10: 550000 | C10: 0.25
A11: 2-bed flat | B11: 850000 | C11: 0.3
A12: 3-bed / duplex | B12: 1800000 | C12: 0.15
A13: Mix check (must equal 100%) | C13: =SUM(C9:C12) -> 1
A14: Blended average annual rent | B14: =SUMPRODUCT(B9:B12,C9:C12) -> 767500 | F14: Drives every revenue line. Weighted by deal mix, not by inventory mix.
A15: Annual rent inflation | B15: 0.15 | F15: Naira rent inflation. Compounds over 60 months — do not leave at a guess.
A17: FEES & REVENUE MODEL
A18: Agency fee (% of annual rent) | B18: 0.1 | F18: Confirm the real Uyo rate, and whether legal fee stacks.
A19: Inspection fee (₦) | B19: 2000 | F19: Credited against the agency fee when the renter takes the place.
A20: Management fee (% of annual rent) | B20: 0.075 | F20: Recurring. The compounding part of the business.
A21: Management attach rate (% of closes) | B21: 0.25 | F21: Share of closed deals whose landlord signs management.
A22: Management layer starts (month) | B22: 13 | F22: Do not open this before you have landlord relationships.
A23: Managed-unit annual churn | B23: 0.1 | F23: Landlords who leave or sell.
A25: AGENT FUNNEL
A26: Listings verified / effective agent / month | B26: 6 | F26: Governed by your Verification SOP. Time it in the field.
A27: Inspections / effective agent / month | B27: 40 | F27: Agent capacity ceiling — roughly 2 a working day.
A28: Max inspections / active listing / month | B28: 3 | F28: Inventory ceiling. Model takes the LOWER of the two.
A29: Inspection → close conversion | B29: 0.12 | F29: The single most sensitive number in the model.
A30: Listing churn / month | B30: 0.08 | F30: Let elsewhere, withdrawn, or gone stale.
A31: Agent ramp — month 1 productivity | B31: 0.4
A32: Agent ramp — month 2 productivity | B32: 0.75 | F32: Full productivity from month 3.
A33: Agent attrition / month | B33: 0.03 | F33: ~30%/yr. Field roles churn. Do not set this to zero.
A35: AGENT ECONOMICS
A36: Agent monthly stipend (₦) | B36: 80000 | F36: Keep low; the commission should be the real pay.
A37: Agent commission (% of agency fee) | B37: 0.3 | F37: Paid on rent collected, not on handshake.
A38: Agent commission on sales (% of sale commission) | B38: 0.3
A40: HIRING PLAN
A41: Year | B41: Agents hired / month
A42: 1 | B42: 1 | F42: This is the real growth constraint. You grow at the speed you can hire and train, not the speed you can code.
A43: 2 | B43: 2
A44: 3 | B44: 3
A45: 4 | B45: 4
A46: 5 | B46: 5
A47: Agents at launch (month 1) | B47: 2 | F47: Assumed already trained.
A49: CITY EXPANSION — TRIGGER-BASED, NOT DATE-BASED
...

Sheet Monthly Model
A1: UNO — Monthly Operating Model (60 months)
A2: All formulas. Every input lives on the Assumptions tab.
A3: Month | B3: Year | C3: Cities live | D3: Agents hired | E3: Agents (EOM) | F3: Effective agents | G3: New listings verified | H3: Opening inventory | I3: Inspections | J3: Rental deals closed | K3: Closing inventory | L3: Blended annual rent | M3: Agency fee revenue | N3: Inspection revenue (net) | O3: Managed units | P3: Management revenue | Q3: Sale deals | R3: Sales revenue | S3: TOTAL REVENUE | T3: Agent commission | U3: Agent stipends | V3: Total agent cost | W3: Gross profit | X3: Gross margin % | Y3: Core team | Z3: Tech & infra | AA3: Marketing | AB3: Office & admin | AC3: City opening cost | AD3: Total opex | AE3: EBITDA | AF3: Cumulative cash
A4: 1 | B4: =ROUNDUP(A4/12,0) -> 1 | C4: =COUNTIF(Assumptions!$B$51:$B$57,"<="&A4) -> 1 | D4: =INDEX(Assumptions!$B$42:$B$46,MATCH(B4,Assumptions!$A$42:$A$46,0)) -> 1 | E4: =Assumptions!$B$47+D4 -> 3 | F4: =MAX(0,E4-D4*(1-Assumptions!$B$31)) -> 2.4 | G4: =F4*Assumptions!$B$26 -> 14.4 | H4: =G4 -> 14.4 | I4: =MIN(F4*Assumptions!$B$27,H4*Assumptions!$B$28) -> 43.2 | J4: =I4*Assumptions!$B$29 -> 5.184 | K4: =MAX(0,H4-J4)*(1-Assumptions!$B$30) -> 8.47872 | L4: =Assumptions!$B$14*(1+Assumptions!$B$15)^((A4-1)/12) -> 767500 | M4: =J4*L4*Assumptions!$B$18 -> 397872 | N4: =MAX(0,I4-J4)*Assumptions!$B$19 -> 76032 | O4: =IF(A4>=Assumptions!$B$22,J4*Assumptions!$B$21,0) -> 0 | P4: =O4*L4*Assumptions!$B$20/12 -> 0 | Q4: =IF(A4>=Assumptions!$B$61,(A4-Assumptions!$B$61+1)*Assumptions!$B$64,0) -> 0 | R4: =Q4*Assumptions!$B$62*Assumptions!$B$63 -> 0 | S4: =M4+N4+P4+R4 -> 473904 | T4: =M4*Assumptions!$B$37+R4*Assumptions!$B$38 -> 119361.6 | U4: =E4*Assumptions!$B$36 -> 240000 | V4: =T4+U4 -> 359361.6 | W4: =S4-V4 -> 114542.4 | X4: =IFERROR(W4/S4,0) -> 0.24169958 | Y4: =INDEX(Assumptions!$B$68:$B$72,MATCH(B4,Assumptions!$A$68:$A$72,0)) -> 1200000 | Z4: =INDEX(Assumptions!$C$68:$C$72,MATCH(B4,Assumptions!$A$68:$A$72,0)) -> 150000 | AA4: =INDEX(Assumptions!$D$68:$D$72,MATCH(B4,Assumptions!$A$68:$A$72,0)) -> 300000 | AB4: =INDEX(Assumptions!$E$68:$E$72,MATCH(B4,Assumptions!$A$68:$A$72,0)) -> 250000 | AC4: =C4*Assumptions!$B$58 -> 1500000 | AD4: =SUM(Y4:AC4) -> 3400000 | AE4: =W4-AD4 -> -3285457.6 | AF4: =Assumptions!$B$74+AE4 -> -3285457.6
A5: 2 | B5: =ROUNDUP(A5/12,0) -> 1 | C5: =COUNTIF(Assumptions!$B$51:$B$57,"<="&A5) -> 1 | D5: =INDEX(Assumptions!$B$42:$B$46,MATCH(B5,Assumptions!$A$42:$A$46,0)) -> 1 | E5: =E4*(1-Assumptions!$B$33)+D5 -> 3.91 | F5: =MAX(0,E5-D5*(1-Assumptions!$B$31)-D4*(1-Assumptions!$B$32)) -> 3.06 | G5: =F5*Assumptions!$B$26 -> 18.36 | H5: =K4+G5 -> 26.83872 | I5: =MIN(F5*Assumptions!$B$27,H5*Assumptions!$B$28) -> 80.51616 | J5: =I5*Assumptions!$B$29 -> 9.6619392 | K5: =MAX(0,H5-J5)*(1-Assumptions!$B$30) -> 15.802638 | L5: =Assumptions!$B$14*(1+Assumptions!$B$15)^((A5-1)/12) -> 776491.2 | M5: =J5*L5*Assumptions!$B$18 -> 750241.08 | N5: =MAX(0,I5-J5)*Assumptions!$B$19 -> 141708.44 | O5: =O4*(1-Assumptions!$B$23/12)+IF(A5>=Assumptions!$B$22,J5*Assumptions!$B$21,0) -> 0 | P5: =O5*L5*Assumptions!$B$20/12 -> 0 | Q5: =IF(A5>=Assumptions!$B$61,(A5-Assumptions!$B$61+1)*Assumptions!$B$64,0) -> 0 | R5: =Q5*Assumptions!$B$62*Assumptions!$B$63 -> 0 | S5: =M5+N5+P5+R5 -> 891949.52 | T5: =M5*Assumptions!$B$37+R5*Assumptions!$B$38 -> 225072.32 | U5: =E5*Assumptions!$B$36 -> 312800 | V5: =T5+U5 -> 537872.32 | W5: =S5-V5 -> 354077.19 | X5: =IFERROR(W5/S5,0) -> 0.39696999 | Y5: =INDEX(Assumptions!$B$68:$B$72,MATCH(B5,Assumptions!$A$68:$A$72,0)) -> 1200000 | Z5: =INDEX(Assumptions!$C$68:$C$72,MATCH(B5,Assumptions!$A$68:$A$72,0)) -> 150000 | AA5: =INDEX(Assumptions!$D$68:$D$72,MATCH(B5,Assumptions!$A$68:$A$72,0)) -> 300000 | AB5: =INDEX(Assumptions!$E$68:$E$72,MATCH(B5,Assumptions!$A$68:$A$72,0)) -> 250000 | AC5: =MAX(0,C5-C4)*Assumptions!$B$58 -> 0 | AD5: =SUM(Y5:AC5) -> 1900000 | AE5: =W5-AD5 -> -1545922.8 | AF5: =AF4+AE5 -> -4831380.4
A6: 3 | B6: =ROUNDUP(A6/12,0) -> 1 | C6: =COUNTIF(Assumptions!$B$51:$B$57,"<="&A6) -> 1 | D6: =INDEX(Assumptions!$B$42:$B$46,MATCH(B6,Assumptions!$A$42:$A$46,0)) -> 1 | E6: =E5*(1-Assumptions!$B$33)+D6 -> 4.7927 | F6: =MAX(0,E6-D6*(1-Assumptions!$B$31)-D5*(1-Assumptions!$B$32)) -> 3.9427 | G6: =F6*Assumptions!$B$26 -> 23.6562 | H6: =K5+G6 -> 39.458838 | I6: =MIN(F6*Assumptions!$B$27,H6*Assumptions!$B$28) -> 118.37652 | J6: =I6*Assumptions!$B$29 -> 14.205182 | K6: =MAX(0,H6-J6)*(1-Assumptions!$B$30) -> 23.233364 | L6: =Assumptions!$B$14*(1+Assumptions!$B$15)^((A6-1)/12) -> 785587.73 | M6: =J6*L6*Assumptions!$B$18 -> 1115941.7 | N6: =MAX(0,I6-J6)*Assumptions!$B$19 -> 208342.67 | O6: =O5*(1-Assumptions!$B$23/12)+IF(A6>=Assumptions!$B$22,J6*Assumptions!$B$21,0) -> 0 | P6: =O6*L6*Assumptions!$B$20/12 -> 0 | Q6: =IF(A6>=Assumptions!$B$61,(A6-Assumptions!$B$61+1)*Assumptions!$B$64,0) -> 0 | R6: =Q6*Assumptions!$B$62*Assumptions!$B$63 -> 0 | S6: =M6+N6+P6+R6 -> 1324284.3 | T6: =M6*Assumptions!$B$37+R6*Assumptions!$B$38 -> 334782.5 | U6: =E6*Assumptions!$B$36 -> 383416 | V6: =T6+U6 -> 718198.5 | W6: =S6-V6 -> 606085.82 | X6: =IFERROR(W6/S6,0) -> 0.45767047 | Y6: =INDEX(Assumptions!$B$68:$B$72,MATCH(B6,Assumptions!$A$68:$A$72,0)) -> 1200000 | Z6: =INDEX(Assumptions!$C$68:$C$72,MATCH(B6,Assumptions!$A$68:$A$72,0)) -> 150000 | AA6: =INDEX(Assumptions!$D$68:$D$72,MATCH(B6,Assumptions!$A$68:$A$72,0)) -> 300000 | AB6: =INDEX(Assumptions!$E$68:$E$72,MATCH(B6,Assumptions!$A$68:$A$72,0)) -> 250000 | AC6: =MAX(0,C6-C5)*Assumptions!$B$58 -> 0 | AD6: =SUM(Y6:AC6) -> 1900000 | AE6: =W6-AD6 -> -1293914.2 | AF6: =AF5+AE6 -> -6125294.6
A7: 4 | B7: =ROUNDUP(A7/12,0) -> 1 | C7: =COUNTIF(Assumptions!$B$51:$B$57,"<="&A7) -> 1 | D7: =INDEX(Assumptions!$B$42:$B$46,MATCH(B7,Assumptions!$A$42:$A$46,0)) -> 1 | E7: =E6*(1-Assumptions!$B$33)+D7 -> 5.648919 | F7: =MAX(0,E7-D7*(1-Assumptions!$B$31)-D6*(1-Assumptions!$B$32)) -> 4.798919 | G7: =F7*Assumptions!$B$26 -> 28.793514 | H7: =K6+G7 -> 52.026878 | I7: =MIN(F7*Assumptions!$B$27,H7*Assumptions!$B$28) -> 156.08063 | J7: =I7*Assumptions!$B$29 -> 18.729676 | K7: =MAX(0,H7-J7)*(1-Assumptions!$B$30) -> 30.633426 | L7: =Assumptions!$B$14*(1+Assumptions!$B$15)^((A7-1)/12) -> 794790.82 | M7: =J7*L7*Assumptions!$B$18 -> 1488617.5 | N7: =MAX(0,I7-J7)*Assumptions!$B$19 -> 274701.92 | O7: =O6*(1-Assumptions!$B$23/12)+IF(A7>=Assumptions!$B$22,J7*Assumptions!$B$21,0) -> 0 | P7: =O7*L7*Assumptions!$B$20/12 -> 0 | Q7: =IF(A7>=Assumptions!$B$61,(A7-Assumptions!$B$61+1)*Assumptions!$B$64,0) -> 0 | R7: =Q7*Assumptions!$B$62*Assumptions!$B$63 -> 0 | S7: =M7+N7+P7+R7 -> 1763319.4 | T7: =M7*Assumptions!$B$37+R7*Assumptions!$B$38 -> 446585.24 | U7: =E7*Assumptions!$B$36 -> 451913.52 | V7: =T7+U7 -> 898498.76 | W7: =S7-V7 -> 864820.62 | X7: =IFERROR(W7/S7,0) -> 0.49045036 | Y7: =INDEX(Assumptions!$B$68:$B$72,MATCH(B7,Assumptions!$A$68:$A$72,0)) -> 1200000 | Z7: =INDEX(Assumptions!$C$68:$C$72,MATCH(B7,Assumptions!$A$68:$A$72,0)) -> 150000 | AA7: =INDEX(Assumptions!$D$68:$D$72,MATCH(B7,Assumptions!$A$68:$A$72,0)) -> 300000 | AB7: =INDEX(Assumptions!$E$68:$E$72,MATCH(B7,Assumptions!$A$68:$A$72,0)) -> 250000 | AC7: =MAX(0,C7-C6)*Assumptions!$B$58 -> 0 | AD7: =SUM(Y7:AC7) -> 1900000 | AE7: =W7-AD7 -> -1035179.4 | AF7: =AF6+AE7 -> -7160474
A8: 5 | B8: =ROUNDUP(A8/12,0) -> 1 | C8: =COUNTIF(Assumptions!$B$51:$B$57,"<="&A8) -> 1 | D8: =INDEX(Assumptions!$B$42:$B$46,MATCH(B8,Assumptions!$A$42:$A$46,0)) -> 1 | E8: =E7*(1-Assumptions!$B$33)+D8 -> 6.4794514 | F8: =MAX(0,E8-D8*(1-Assumptions!$B$31)-D7*(1-Assumptions!$B$32)) -> 5.6294514 | G8: =F8*Assumptions!$B$26 -> 33.776709 | H8: =K7+G8 -> 64.410134 | I8: =MIN(F8*Assumptions!$B$27,H8*Assumptions!$B$28) -> 193.2304 | J8: =I8*Assumptions!$B$29 -> 23.187648 | K8: =MAX(0,H8-J8)*(1-Assumptions!$B$30) -> 37.924687 | L8: =Assumptions!$B$14*(1+Assumptions!$B$15)^((A8-1)/12) -> 804101.73 | M8: =J8*L8*Assumptions!$B$18 -> 1864522.8 | N8: =MAX(0,I8-J8)*Assumptions!$B$19 -> 340085.51 | O8: =O7*(1-Assumptions!$B$23/12)+IF(A8>=Assumptions!$B$22,J8*Assumptions!$B$21,0) -> 0 | P8: =O8*L8*Assumptions!$B$20/12 -> 0 | Q8: =IF(A8>=Assumptions!$B$61,(A8-Assumptions!$B$61+1)*Assumptions!$B$64,0) -> 0 | R8: =Q8*Assumptions!$B$62*Assumptions!$B$63 -> 0 | S8: =M8+N8+P8+R8 -> 2204608.3 | T8: =M8*Assumptions!$B$37+R8*Assumptions!$B$38 -> 559356.85 | U8: =E8*Assumptions!$B$36 -> 518356.11 | V8: =T8+U8 -> 1077713 | W8: =S8-V8 -> 1126895.4 | X8: =IFERROR(W8/S8,0) -> 0.51115446 | Y8: =INDEX(Assumptions!$B$68:$B$72,MATCH(B8,Assumptions!$A$68:$A$72,0)) -> 1200000 | Z8: =INDEX(Assumptions!$C$68:$C$72,MATCH(B8,Assumptions!$A$68:$A$72,0)) -> 150000 | AA8: =INDEX(Assumptions!$D$68:$D$72,MATCH(B8,Assumptions!$A$68:$A$72,0)) -> 300000 | AB8: =INDEX(Assumptions!$E$68:$E$72,MATCH(B8,Assumptions!$A$68:$A$72,0)) -> 250000 | AC8: =MAX(0,C8-C7)*Assumptions!$B$58 -> 0 | AD8: =SUM(Y8:AC8) -> 1900000 | AE8: =W8-AD8 -> -773104.63 | AF8: =AF7+AE8 -> -7933578.6
A9: 6 | B9: =ROUNDUP(A9/12,0) -> 1 | C9: =COUNTIF(Assumptions!$B$51:$B$57,"<="&A9) -> 1 | D9: =INDEX(Assumptions!$B$42:$B$46,MATCH(B9,Assumptions!$A$42:$A$46,0)) -> 1 | E9: =E8*(1-Assumptions!$B$33)+D9 -> 7.2850679 | F9: =MAX(0,E9-D9*(1-Assumptions!$B$31)-D8*(1-Assumptions!$B$32)) -> 6.4350679 | G9: =F9*Assumptions!$B$26 -> 38.610407 | H9: =K8+G9 -> 76.535094 | I9: =MIN(F9*Assumptions!$B$27,H9*Assumptions!$B$28) -> 229.60528 | J9: =I9*Assumptions!$B$29 -> 27.552634 | K9: =MAX(0,H9-J9)*(1-Assumptions!$B$30) -> 45.063864 | L9: =Assumptions!$B$14*(1+Assumptions!$B$15)^((A9-1)/12) -> 813521.72 | M9: =J9*L9*Assumptions!$B$18 -> 2241466.6 | N9: =MAX(0,I9-J9)*Assumptions!$B$19 -> 404105.3 | O9: =O8*(1-Assumptions!$B$23/12)+IF(A9>=Assumptions!$B$22,J9*Assumptions!$B$21,0) -> 0 | P9: =O9*L9*Assumptions!$B$20/12 -> 0 | Q9: =IF(A9>=Assumptions!$B$61,(A9-Assumptions!$B$61+1)*Assumptions!$B$64,0) -> 0 | R9: =Q9*Assumptions!$B$62*Assumptions!$B$63 -> 0 | S9: =M9+N9+P9+R9 -> 2645571.9 | T9: =M9*Assumptions!$B$37+R9*Assumptions!$B$38 -> 672439.98 | U9: =E9*Assumptions!$B$36 -> 582805.43 | V9: =T9+U9 -> 1255245.4 | W9: =S9-V9 -> 1390326.5 | X9: =IFERROR(W9/S9,0) -> 0.52552966 | Y9: =INDEX(Assumptions!$B$68:$B$72,MATCH(B9,Assumptions!$A$68:$A$72,0)) -> 1200000 | Z9: =INDEX(Assumptions!$C$68:$C$72,MATCH(B9,Assumptions!$A$68:$A$72,0)) -> 150000 | AA9: =INDEX(Assumptions!$D$68:$D$72,MATCH(B9,Assumptions!$A$68:$A$72,0)) -> 300000 | AB9: =INDEX(Assumptions!$E$68:$E$72,MATCH(B9,Assumptions!$A$68:$A$72,0)) -> 250000 | AC9: =MAX(0,C9-C8)*Assumptions!$B$58 -> 0 | AD9: =SUM(Y9:AC9) -> 1900000 | AE9: =W9-AD9 -> -509673.5 | AF9: =AF8+AE9 -> -8443252.1
A10: 7 | B10: =ROUNDUP(A10/12,0) -> 1 | C10: =COUNTIF(Assumptions!$B$51:$B$57,"<="&A10) -> 1 | D10: =INDEX(Assumptions!$B$42:$B$46,MATCH(B10,Assumptions!$A$42:$A$46,0)) -> 1 | E10: =E9*(1-Assumptions!$B$33)+D10 -> 8.0665159 | F10: =MAX(0,E10-D10*(1-Assumptions!$B$31)-D9*(1-Assumptions!$B$32)) -> 7.2165159 | G10: =F10*Assumptions!$B$26 -> 43.299095 | H10: =K9+G10 -> 88.362959 | I10: =MIN(F10*Assumptions!$B$27,H10*Assumptions!$B$28) -> 265.08888 | J10: =I10*Assumptions!$B$29 -> 31.810665 | K10: =MAX(0,H10-J10)*(1-Assumptions!$B$30) -> 52.02811 | L10: =Assumptions!$B$14*(1+Assumptions!$B$15)^((A10-1)/12) -> 823052.06 | M10: =J10*L10*Assumptions!$B$18 -> 2618183.3 | N10: =MAX(0,I10-J10)*Assumptions!$B$19 -> 466556.42 | O10: =O9*(1-Assumptions!$B$23/12)+IF(A10>=Assumptions!$B$22,J10*Assumptions!$B$21,0) -> 0 | P10: =O10*L10*Assumptions!$B$20/12 -> 0 | Q10: =IF(A10>=Assumptions!$B$61,(A10-Assumptions!$B$61+1)*Assumptions!$B$64,0) -> 0 | R10: =Q10*Assumptions!$B$62*Assumptions!$B$63 -> 0 | S10: =M10+N10+P10+R10 -> 3084739.8 | T10: =M10*Assumptions!$B$37+R10*Assumptions!$B$38 -> 785455 | U10: =E10*Assumptions!$B$36 -> 645321.27 | V10: =T10+U10 -> 1430776.3 | W10: =S10-V10 -> 1653963.5 | X10: =IFERROR(W10/S10,0) -> 0.53617602 | Y10: =INDEX(Assumptions!$B$68:$B$72,MATCH(B10,Assumptions!$A$68:$A$72,0)) -> 1200000 | Z10: =INDEX(Assumptions!$C$68:$C$72,MATCH(B10,Assumptions!$A$68:$A$72,0)) -> 150000 | AA10: =INDEX(Assumptions!$D$68:$D$72,MATCH(B10,Assumptions!$A$68:$A$72,0)) -> 300000 | AB10: =INDEX(Assumptions!$E$68:$E$72,MATCH(B10,Assumptions!$A$68:$A$72,0)) -> 250000 | AC10: =MAX(0,C10-C9)*Assumptions!$B$58 -> 0 | AD10: =SUM(Y10:AC10) -> 1900000 | AE10: =W10-AD10 -> -246036.51 | AF10: =AF9+AE10 -> -8689288.6
A11: 8 | B11: =ROUNDUP(A11/12,0) -> 1 | C11: =COUNTIF(Assumptions!$B$51:$B$57,"<="&A11) -> 1 | D11: =INDEX(Assumptions!$B$42:$B$46,MATCH(B11,Assumptions!$A$42:$A$46,0)) -> 1 | E11: =E10*(1-Assumptions!$B$33)+D11 -> 8.8245204 | F11: =MAX(0,E11-D11*(1-Assumptions!$B$31)-D10*(1-Assumptions!$B$32)) -> 7.9745204 | G11: =F11*Assumptions!$B$26 -> 47.847122 | H11: =K10+G11 -> 99.875232 | I11: =MIN(F11*Assumptions!$B$27,H11*Assumptions!$B$28) -> 299.6257 | J11: =I11*Assumptions!$B$29 -> 35.955084 | K11: =MAX(0,H11-J11)*(1-Assumptions!$B$30) -> 58.806537 | L11: =Assumptions!$B$14*(1+Assumptions!$B$15)^((A11-1)/12) -> 832694.04 | M11: =J11*L11*Assumptions!$B$18 -> 2993958.4 | N11: =MAX(0,I11-J11)*Assumptions!$B$19 -> 527341.23 | O11: =O10*(1-Assumptions!$B$23/12)+IF(A11>=Assumptions!$B$22,J11*Assumptions!$B$21,0) -> 0 | P11: =O11*L11*Assumptions!$B$20/12 -> 0 | Q11: =IF(A11>=Assumptions!$B$61,(A11-Assumptions!$B$61+1)*Assumptions!$B$64,0) -> 0 | R11: =Q11*Assumptions!$B$62*Assumptions!$B$63 -> 0 | S11: =M11+N11+P11+R11 -> 3521299.6 | T11: =M11*Assumptions!$B$37+R11*Assumptions!$B$38 -> 898187.52 | U11: =E11*Assumptions!$B$36 -> 705961.63 | V11: =T11+U11 -> 1604149.1 | W11: =S11-V11 -> 1917150.5 | X11: =IFERROR(W11/S11,0) -> 0.54444401 | Y11: =INDEX(Assumptions!$B$68:$B$72,MATCH(B11,Assumptions!$A$68:$A$72,0)) -> 1200000 | Z11: =INDEX(Assumptions!$C$68:$C$72,MATCH(B11,Assumptions!$A$68:$A$72,0)) -> 150000 | AA11: =INDEX(Assumptions!$D$68:$D$72,MATCH(B11,Assumptions!$A$68:$A$72,0)) -> 300000 | AB11: =INDEX(Assumptions!$E$68:$E$72,MATCH(B11,Assumptions!$A$68:$A$72,0)) -> 250000 | AC11: =MAX(0,C11-C10)*Assumptions!$B$58 -> 0 | AD11: =SUM(Y11:AC11) -> 1900000 | AE11: =W11-AD11 -> 17150.474 | AF11: =AF10+AE11 -> -8672138.1
A12: 9 | B12: =ROUNDUP(A12/12,0) -> 1 | C12: =COUNTIF(Assumptions!$B$51:$B$57,"<="&A12) -> 1 | D12: =INDEX(Assumptions!$B$42:$B$46,MATCH(B12,Assumptions!$A$42:$A$46,0)) -> 1 | E12: =E11*(1-Assumptions!$B$33)+D12 -> 9.5597848 | F12: =MAX(0,E12-D12*(1-Assumptions!$B$31)-D11*(1-Assumptions!$B$32)) -> 8.7097848 | G12: =F12*Assumptions!$B$26 -> 52.258709 | H12: =K11+G12 -> 111.06525 | I12: =MIN(F12*Assumptions!$B$27,H12*Assumptions!$B$28) -> 333.19574 | J12: =I12*Assumptions!$B$29 -> 39.983488 | K12: =MAX(0,H12-J12)*(1-Assumptions!$B$30) -> 65.395216 | L12: =Assumptions!$B$14*(1+Assumptions!$B$15)^((A12-1)/12) -> 842448.98 | M12: =J12*L12*Assumptions!$B$18 -> 3368404.9 | N12: =MAX(0,I12-J12)*Assumptions!$B$19 -> 586424.5 | O12: =O11*(1-Assumptions!$B$23/12)+IF(A12>=Assumptions!$B$22,J12*Assumptions!$B$21,0) -> 0 | P12: =O12*L12*Assumptions!$B$20/12 -> 0 | Q12: =IF(A12>=Assumptions!$B$61,(A12-Assumptions!$B$61+1)*Assumptions!$B$64,0) -> 0 | R12: =Q12*Assumptions!$B$62*Assumptions!$B$63 -> 0 | S12: =M12+N12+P12+R12 -> 3954829.4 | T12: =M12*Assumptions!$B$37+R12*Assumptions!$B$38 -> 1010521.5 | U12: =E12*Assumptions!$B$36 -> 764782.78 | V12: =T12+U12 -> 1775304.3 | W12: =S12-V12 -> 2179525.2 | X12: =IFERROR(W12/S12,0) -> 0.55110472 | Y12: =INDEX(Assumptions!$B$68:$B$72,MATCH(B12,Assumptions!$A$68:$A$72,0)) -> 1200000 | Z12: =INDEX(Assumptions!$C$68:$C$72,MATCH(B12,Assumptions!$A$68:$A$72,0)) -> 150000 | AA12: =INDEX(Assumptions!$D$68:$D$72,MATCH(B12,Assumptions!$A$68:$A$72,0)) -> 300000 | AB12: =INDEX(Assumptions!$E$68:$E$72,MATCH(B12,Assumptions!$A$68:$A$72,0)) -> 250000 | AC12: =MAX(0,C12-C11)*Assumptions!$B$58 -> 0 | AD12: =SUM(Y12:AC12) -> 1900000 | AE12: =W12-AD12 -> 279525.15 | AF12: =AF11+AE12 -> -8392613
A13: 10 | B13: =ROUNDUP(A13/12,0) -> 1 | C13: =COUNTIF(Assumptions!$B$51:$B$57,"<="&A13) -> 1 | D13: =INDEX(Assumptions!$B$42:$B$46,MATCH(B13,Assumptions!$A$42:$A$46,0)) -> 1 | E13: =E12*(1-Assumptions!$B$33)+D13 -> 10.272991 | F13: =MAX(0,E13-D13*(1-Assumptions!$B$31)-D12*(1-Assumptions!$B$32)) -> 9.4229912 | G13: =F13*Assumptions!$B$26 -> 56.537947 | H13: =K12+G13 -> 121.93316 | I13: =MIN(F13*Assumptions!$B$27,H13*Assumptions!$B$28) -> 365.79949 | J13: =I13*Assumptions!$B$29 -> 43.895939 | K13: =MAX(0,H13-J13)*(1-Assumptions!$B$30) -> 71.794247 | L13: =Assumptions!$B$14*(1+Assumptions!$B$15)^((A13-1)/12) -> 852318.2 | M13: =J13*L13*Assumptions!$B$18 -> 3741330.8 | N13: =MAX(0,I13-J13)*Assumptions!$B$19 -> 643807.1 | O13: =O12*(1-Assumptions!$B$23/12)+IF(A13>=Assumptions!$B$22,J13*Assumptions!$B$21,0) -> 0 | P13: =O13*L13*Assumptions!$B$20/12 -> 0 | Q13: =IF(A13>=Assumptions!$B$61,(A13-Assumptions!$B$61+1)*Assumptions!$B$64,0) -> 0 | R13: =Q13*Assumptions!$B$62*Assumptions!$B$63 -> 0 | S13: =M13+N13+P13+R13 -> 4385137.9 | T13: =M13*Assumptions!$B$37+R13*Assumptions!$B$38 -> 1122399.2 | U13: =E13*Assumptions!$B$36 -> 821839.3 | V13: =T13+U13 -> 1944238.5 | W13: =S13-V13 -> 2440899.4 | X13: =IFERROR(W13/S13,0) -> 0.55663001 | Y13: =INDEX(Assumptions!$B$68:$B$72,MATCH(B13,Assumptions!$A$68:$A$72,0)) -> 1200000 | Z13: =INDEX(Assumptions!$C$68:$C$72,MATCH(B13,Assumptions!$A$68:$A$72,0)) -> 150000 | AA13: =INDEX(Assumptions!$D$68:$D$72,MATCH(B13,Assumptions!$A$68:$A$72,0)) -> 300000 | AB13: =INDEX(Assumptions!$E$68:$E$72,MATCH(B13,Assumptions!$A$68:$A$72,0)) -> 250000 | AC13: =MAX(0,C13-C12)*Assumptions!$B$58 -> 0 | AD13: =SUM(Y13:AC13) -> 1900000 | AE13: =W13-AD13 -> 540899.36 | AF13: =AF12+AE13 -> -7851713.6
A14: 11 | B14: =ROUNDUP(A14/12,0) -> 1 | C14: =COUNTIF(Assumptions!$B$51:$B$57,"<="&A14) -> 1 | D14: =INDEX(Assumptions!$B$42:$B$46,MATCH(B14,Assumptions!$A$42:$A$46,0)) -> 1 | E14: =E13*(1-Assumptions!$B$33)+D14 -> 10.964801 | F14: =MAX(0,E14-D14*(1-Assumptions!$B$31)-D13*(1-Assumptions!$B$32)) -> 10.114801 | G14: =F14*Assumptions!$B$26 -> 60.688809 | H14: =K13+G14 -> 132.48306 | I14: =MIN(F14*Assumptions!$B$27,H14*Assumptions!$B$28) -> 397.44917 | J14: =I14*Assumptions!$B$29 -> 47.6939 | K14: =MAX(0,H14-J14)*(1-Assumptions!$B$30) -> 78.006023 | L14: =Assumptions!$B$14*(1+Assumptions!$B$15)^((A14-1)/12) -> 862303.04 | M14: =J14*L14*Assumptions!$B$18 -> 4112659.5 | N14: =MAX(0,I14-J14)*Assumptions!$B$19 -> 699510.53 | O14: =O13*(1-Assumptions!$B$23/12)+IF(A14>=Assumptions!$B$22,J14*Assumptions!$B$21,0) -> 0 | P14: =O14*L14*Assumptions!$B$20/12 -> 0 | Q14: =IF(A14>=Assumptions!$B$61,(A14-Assumptions!$B$61+1)*Assumptions!$B$64,0) -> 0 | R14: =Q14*Assumptions!$B$62*Assumptions!$B$63 -> 0 | S14: =M14+N14+P14+R14 -> 4812170 | T14: =M14*Assumptions!$B$37+R14*Assumptions!$B$38 -> 1233797.9 | U14: =E14*Assumptions!$B$36 -> 877184.12 | V14: =T14+U14 -> 2110982 | W14: =S14-V14 -> 2701188.1 | X14: =IFERROR(W14/S14,0) -> 0.56132432 | Y14: =INDEX(Assumptions!$B$68:$B$72,MATCH(B14,Assumptions!$A$68:$A$72,0)) -> 1200000 | Z14: =INDEX(Assumptions!$C$68:$C$72,MATCH(B14,Assumptions!$A$68:$A$72,0)) -> 150000 | AA14: =INDEX(Assumptions!$D$68:$D$72,MATCH(B14,Assumptions!$A$68:$A$72,0)) -> 300000 | AB14: =INDEX(Assumptions!$E$68:$E$72,MATCH(B14,Assumptions!$A$68:$A$72,0)) -> 250000 | AC14: =MAX(0,C14-C13)*Assumptions!$B$58 -> 0 | AD14: =SUM(Y14:AC14) -> 1900000 | AE14: =W14-AD14 -> 801188.07 | AF14: =AF13+AE14 -> -7050525.5
A15: 12 | B15: =ROUNDUP(A15/12,0) -> 1 | C15: =COUNTIF(Assumptions!$B$51:$B$57,"<="&A15) -> 1 | D15: =INDEX(Assumptions!$B$42:$B$46,MATCH(B15,Assumptions!$A$42:$A$46,0)) -> 1 | E15: =E14*(1-Assumptions!$B$33)+D15 -> 11.635857 | F15: =MAX(0,E15-D15*(1-Assumptions!$B$31)-D14*(1-Assumptions!$B$32)) -> 10.785857 | G15: =F15*Assumptions!$B$26 -> 64.715145 | H15: =K14+G15 -> 142.72117 | I15: =MIN(F15*Assumptions!$B$27,H15*Assumptions!$B$28) -> 428.1635 | J15: =I15*Assumptions!$B$29 -> 51.37962 | K15: =MAX(0,H15-J15)*(1-Assumptions!$B$30) -> 84.034224 | L15: =Assumptions!$B$14*(1+Assumptions!$B$15)^((A15-1)/12) -> 872404.85 | M15: =J15*L15*Assumptions!$B$18 -> 4482383 | N15: =MAX(0,I15-J15)*Assumptions!$B$19 -> 753567.77 | O15: =O14*(1-Assumptions!$B$23/12)+IF(A15>=Assumptions!$B$22,J15*Assumptions!$B$21,0) -> 0 | P15: =O15*L15*Assumptions!$B$20/12 -> 0 | Q15: =IF(A15>=Assumptions!$B$61,(A15-Assumptions!$B$61+1)*Assumptions!$B$64,0) -> 0 | R15: =Q15*Assumptions!$B$62*Assumptions!$B$63 -> 0 | S15: =M15+N15+P15+R15 -> 5235950.8 | T15: =M15*Assumptions!$B$37+R15*Assumptions!$B$38 -> 1344714.9 | U15: =E15*Assumptions!$B$36 -> 930868.6 | V15: =T15+U15 -> 2275583.5 | W15: =S15-V15 -> 2960367.3 | X15: =IFERROR(W15/S15,0) -> 0.5653925 | Y15: =INDEX(Assumptions!$B$68:$B$72,MATCH(B15,Assumptions!$A$68:$A$72,0)) -> 1200000 | Z15: =INDEX(Assumptions!$C$68:$C$72,MATCH(B15,Assumptions!$A$68:$A$72,0)) -> 150000 | AA15: =INDEX(Assumptions!$D$68:$D$72,MATCH(B15,Assumptions!$A$68:$A$72,0)) -> 300000 | AB15: =INDEX(Assumptions!$E$68:$E$72,MATCH(B15,Assumptions!$A$68:$A$72,0)) -> 250000 | AC15: =MAX(0,C15-C14)*Assumptions!$B$58 -> 0 | AD15: =SUM(Y15:AC15) -> 1900000 | AE15: =W15-AD15 -> 1060367.3 | AF15: =AF14+AE15 -> -5990158.3
A16: 13 | B16: =ROUNDUP(A16/12,0) -> 2 | C16: =COUNTIF(Assumptions!$B$51:$B$57,"<="&A16) -> 2 | D16: =INDEX(Assumptions!$B$42:$B$46,MATCH(B16,Assumptions!$A$42:$A$46,0)) -> 2 | E16: =E15*(1-Assumptions!$B$33)+D16 -> 13.286782 | F16: =MAX(0,E16-D16*(1-Assumptions!$B$31)-D15*(1-Assumptions!$B$32)) -> 11.836782 | G16: =F16*Assumptions!$B$26 -> 71.02069 | H16: =K15+G16 -> 155.05491 | I16: =MIN(F16*Assumptions!$B$27,H16*Assumptions!$B$28) -> 465.16474 | J16: =I16*Assumptions!$B$29 -> 55.819769 | K16: =MAX(0,H16-J16)*(1-Assumptions!$B$30) -> 91.296333 | L16: =Assumptions!$B$14*(1+Assumptions!$B$15)^((A16-1)/12) -> 882625 | M16: =J16*L16*Assumptions!$B$18 -> 4926792.4 | N16: =MAX(0,I16-J16)*Assumptions!$B$19 -> 818689.95 | O16: =O15*(1-Assumptions!$B$23/12)+IF(A16>=Assumptions!$B$22,J16*Assumptions!$B$21,0) -> 13.954942 | P16: =O16*L16*Assumptions!$B$20/12 -> 76981.131 | Q16: =IF(A16>=Assumptions!$B$61,(A16-Assumptions!$B$61+1)*Assumptions!$B$64,0) -> 0 | R16: =Q16*Assumptions!$B$62*Assumptions!$B$63 -> 0 | S16: =M16+N16+P16+R16 -> 5822463.4 | T16: =M16*Assumptions!$B$37+R16*Assumptions!$B$38 -> 1478037.7 | U16: =E16*Assumptions!$B$36 -> 1062942.5 | V16: =T16+U16 -> 2540980.2 | W16: =S16-V16 -> 3281483.2 | X16: =IFERROR(W16/S16,0) -> 0.56359018 | Y16: =INDEX(Assumptions!$B$68:$B$72,MATCH(B16,Assumptions!$A$68:$A$72,0)) -> 1500000 | Z16: =INDEX(Assumptions!$C$68:$C$72,MATCH(B16,Assumptions!$A$68:$A$72,0)) -> 250000 | AA16: =INDEX(Assumptions!$D$68:$D$72,MATCH(B16,Assumptions!$A$68:$A$72,0)) -> 700000 | AB16: =INDEX(Assumptions!$E$68:$E$72,MATCH(B16,Assumptions!$A$68:$A$72,0)) -> 400000 | AC16: =MAX(0,C16-C15)*Assumptions!$B$58 -> 1500000 | AD16: =SUM(Y16:AC16) -> 4350000 | AE16: =W16-AD16 -> -1068516.8 | AF16: =AF15+AE16 -> -7058675.1
... A63: 60 | B63: =ROUNDUP(A63/12,0) -> 5 | C63: =COUNTIF(Assumptions!$B$51:$B$57,"<="&A63) -> 7 | D63: =INDEX(Assumptions!$B$42:$B$46,MATCH(B63,Assumptions!$A$42:$A$46,0)) -> 5 | E63: =E62*(1-Assumptions!$B$33)+D63 -> 103.60301 | F63: =MAX(0,E63-D63*(1-Assumptions!$B$31)-D62*(1-Assumptions!$B$32)) -> 99.353012 | G63: =F63*Assumptions!$B$26 -> 596.11807 | H63: =K62+G63 -> 1612.4115 | I63: =MIN(F63*Assumptions!$B$27,H63*Assumptions!$B$28) -> 3974.1205 | J63: =I63*Assumptions!$B$29 -> 476.89446 | K63: =MAX(0,H63-J63)*(1-Assumptions!$B$30) -> 1044.6757 | L63: =Assumptions!$B$14*(1+Assumptions!$B$15)^((A63-1)/12) -> 1525841.5 | M63: =J63*L63*Assumptions!$B$18 -> 72766537 | N63: =MAX(0,I63-J63)*Assumptions!$B$19 -> 6994452 | O63: =O62*(1-Assumptions!$B$23/12)+IF(A63>=Assumptions!$B$22,J63*Assumptions!$B$21,0) -> 2607.8134 | P63: =O63*L63*Assumptions!$B$20/12 -> 24869438 | Q63: =IF(A63>=Assumptions!$B$61,(A63-Assumptions!$B$61+1)*Assumptions!$B$64,0) -> 10.8 | R63: =Q63*Assumptions!$B$62*Assumptions!$B$63 -> 16200000 | S63: =M63+N63+P63+R63 -> 1.2083043e+08 | T63: =M63*Assumptions!$B$37+R63*Assumptions!$B$38 -> 26689961 | U63: =E63*Assumptions!$B$36 -> 8288240.9 | V63: =T63+U63 -> 34978202 | W63: =S63-V63 -> 85852224 | X63: =IFERROR(W63/S63,0) -> 0.71051826 | Y63: =INDEX(Assumptions!$B$68:$B$72,MATCH(B63,Assumptions!$A$68:$A$72,0)) -> 8000000 | Z63: =INDEX(Assumptions!$C$68:$C$72,MATCH(B63,Assumptions!$A$68:$A$72,0)) -> 900000 | AA63: =INDEX(Assumptions!$D$68:$D$72,MATCH(B63,Assumptions!$A$68:$A$72,0)) -> 4000000 | AB63: =INDEX(Assumptions!$E$68:$E$72,MATCH(B63,Assumptions!$A$68:$A$72,0)) -> 1800000 | AC63: =MAX(0,C63-C62)*Assumptions!$B$58 -> 0 | AD63: =SUM(Y63:AC63) -> 14700000 | AE63: =W63-AD63 -> 71152224 | AF63: =AF62+AE63 -> 1.2195899e+09

Sheet Summary
A1: UNO — Annual Summary
A2: Green = pulled from the Monthly Model. Nothing here is typed.
B3: 1 | C3: 2 | D3: 3 | E3: 4 | F3: 5
A5: SCALE
A6: Cities live (end of year) | B6: =INDEX('Monthly Model'!$C$4:$C$63,1*12) -> 1 | C6: =INDEX('Monthly Model'!$C$4:$C$63,2*12) -> 3 | D6: =INDEX('Monthly Model'!$C$4:$C$63,3*12) -> 5 | E6: =INDEX('Monthly Model'!$C$4:$C$63,4*12) -> 6 | F6: =INDEX('Monthly Model'!$C$4:$C$63,5*12) -> 7
A7: Agents (end of year) | B7: =INDEX('Monthly Model'!$E$4:$E$63,1*12) -> 11.635857 | C7: =INDEX('Monthly Model'!$E$4:$E$63,2*12) -> 28.48396 | D7: =INDEX('Monthly Model'!$E$4:$E$63,3*12) -> 50.379142 | E7: =INDEX('Monthly Model'!$E$4:$E$63,4*12) -> 75.776201 | F7: =INDEX('Monthly Model'!$E$4:$E$63,5*12) -> 103.60301
A8: Listings verified in year | B8: =SUMIFS('Monthly Model'!$G$4:$G$63,'Monthly Model'!$B$4:$B$63,1) -> 482.94366 | C8: =SUMIFS('Monthly Model'!$G$4:$G$63,'Monthly Model'!$B$4:$B$63,2) -> 1410.5681 | D8: =SUMIFS('Monthly Model'!$G$4:$G$63,'Monthly Model'!$B$4:$B$63,3) -> 2770.2347 | E8: =SUMIFS('Monthly Model'!$G$4:$G$63,'Monthly Model'!$B$4:$B$63,4) -> 4429.6705 | F8: =SUMIFS('Monthly Model'!$G$4:$G$63,'Monthly Model'!$B$4:$B$63,5) -> 6297.0988
A9: Active inventory (end of year) | B9: =INDEX('Monthly Model'!$K$4:$K$63,1*12) -> 84.034224 | C9: =INDEX('Monthly Model'!$K$4:$K$63,2*12) -> 220.57406 | D9: =INDEX('Monthly Model'!$K$4:$K$63,3*12) -> 431.97216 | E9: =INDEX('Monthly Model'!$K$4:$K$63,4*12) -> 713.24647 | F9: =INDEX('Monthly Model'!$K$4:$K$63,5*12) -> 1044.6757 | G9: The number that matters: verified, transactable inventory.
A10: Inspections in year | B10: =SUMIFS('Monthly Model'!$I$4:$I$63,'Monthly Model'!$B$4:$B$63,1) -> 2910.3315 | C10: =SUMIFS('Monthly Model'!$I$4:$I$63,'Monthly Model'!$B$4:$B$63,2) -> 9281.3408 | D10: =SUMIFS('Monthly Model'!$I$4:$I$63,'Monthly Model'!$B$4:$B$63,3) -> 18468.231 | E10: =SUMIFS('Monthly Model'!$I$4:$I$63,'Monthly Model'!$B$4:$B$63,4) -> 29531.137 | F10: =SUMIFS('Monthly Model'!$I$4:$I$63,'Monthly Model'!$B$4:$B$63,5) -> 41980.659
A11: Rental deals closed in year | B11: =SUMIFS('Monthly Model'!$J$4:$J$63,'Monthly Model'!$B$4:$B$63,1) -> 349.23978 | C11: =SUMIFS('Monthly Model'!$J$4:$J$63,'Monthly Model'!$B$4:$B$63,2) -> 1113.7609 | D11: =SUMIFS('Monthly Model'!$J$4:$J$63,'Monthly Model'!$B$4:$B$63,3) -> 2216.1878 | E11: =SUMIFS('Monthly Model'!$J$4:$J$63,'Monthly Model'!$B$4:$B$63,4) -> 3543.7364 | F11: =SUMIFS('Monthly Model'!$J$4:$J$63,'Monthly Model'!$B$4:$B$63,5) -> 5037.679
A12: Managed units (end of year) | B12: =INDEX('Monthly Model'!$O$4:$O$63,1*12) -> 0 | C12: =INDEX('Monthly Model'!$O$4:$O$63,2*12) -> 267.97454 | D12: =INDEX('Monthly Model'!$O$4:$O$63,3*12) -> 774.16224 | E12: =INDEX('Monthly Model'!$O$4:$O$63,4*12) -> 1549.4715 | F12: =INDEX('Monthly Model'!$O$4:$O$63,5*12) -> 2607.8134 | G12: Recurring revenue base. The moat.
A14: REVENUE
A15: Agency fee revenue | B15: =SUMIFS('Monthly Model'!$M$4:$M$63,'Monthly Model'!$B$4:$B$63,1) -> 29175582 | C15: =SUMIFS('Monthly Model'!$M$4:$M$63,'Monthly Model'!$B$4:$B$63,2) -> 1.0596001e+08 | D15: =SUMIFS('Monthly Model'!$M$4:$M$63,'Monthly Model'!$B$4:$B$63,3) -> 2.4156462e+08 | E15: =SUMIFS('Monthly Model'!$M$4:$M$63,'Monthly Model'!$B$4:$B$63,4) -> 4.4343029e+08 | F15: =SUMIFS('Monthly Model'!$M$4:$M$63,'Monthly Model'!$B$4:$B$63,5) -> 7.2415304e+08
A16: Inspection revenue (net) | B16: =SUMIFS('Monthly Model'!$N$4:$N$63,'Monthly Model'!$B$4:$B$63,1) -> 5122183.4 | C16: =SUMIFS('Monthly Model'!$N$4:$N$63,'Monthly Model'!$B$4:$B$63,2) -> 16335160 | D16: =SUMIFS('Monthly Model'!$N$4:$N$63,'Monthly Model'!$B$4:$B$63,3) -> 32504087 | E16: =SUMIFS('Monthly Model'!$N$4:$N$63,'Monthly Model'!$B$4:$B$63,4) -> 51974800 | F16: =SUMIFS('Monthly Model'!$N$4:$N$63,'Monthly Model'!$B$4:$B$63,5) -> 73885959
A17: Management revenue | B17: =SUMIFS('Monthly Model'!$P$4:$P$63,'Monthly Model'!$B$4:$B$63,1) -> 0 | C17: =SUMIFS('Monthly Model'!$P$4:$P$63,'Monthly Model'!$B$4:$B$63,2) -> 9197159.7 | D17: =SUMIFS('Monthly Model'!$P$4:$P$63,'Monthly Model'!$B$4:$B$63,3) -> 42789480 | E17: =SUMIFS('Monthly Model'!$P$4:$P$63,'Monthly Model'!$B$4:$B$63,4) -> 1.1022575e+08 | F17: =SUMIFS('Monthly Model'!$P$4:$P$63,'Monthly Model'!$B$4:$B$63,5) -> 2.2681373e+08
A18: Sales revenue | B18: =SUMIFS('Monthly Model'!$R$4:$R$63,'Monthly Model'!$B$4:$B$63,1) -> 0 | C18: =SUMIFS('Monthly Model'!$R$4:$R$63,'Monthly Model'!$B$4:$B$63,2) -> 0 | D18: =SUMIFS('Monthly Model'!$R$4:$R$63,'Monthly Model'!$B$4:$B$63,3) -> 35100000 | E18: =SUMIFS('Monthly Model'!$R$4:$R$63,'Monthly Model'!$B$4:$B$63,4) -> 99900000 | F18: =SUMIFS('Monthly Model'!$R$4:$R$63,'Monthly Model'!$B$4:$B$63,5) -> 164700000
A19: TOTAL REVENUE | B19: =SUMIFS('Monthly Model'!$S$4:$S$63,'Monthly Model'!$B$4:$B$63,1) -> 34297765 | C19: =SUMIFS('Monthly Model'!$S$4:$S$63,'Monthly Model'!$B$4:$B$63,2) -> 1.3149233e+08 | D19: =SUMIFS('Monthly Model'!$S$4:$S$63,'Monthly Model'!$B$4:$B$63,3) -> 3.5195818e+08 | E19: =SUMIFS('Monthly Model'!$S$4:$S$63,'Monthly Model'!$B$4:$B$63,4) -> 7.0553085e+08 | F19: =SUMIFS('Monthly Model'!$S$4:$S$63,'Monthly Model'!$B$4:$B$63,5) -> 1.1895527e+09
A21: PROFITABILITY
A22: Total agent cost (commission + stipends) | B22: =SUMIFS('Monthly Model'!$V$4:$V$63,'Monthly Model'!$B$4:$B$63,1) -> 15987923 | C22: =SUMIFS('Monthly Model'!$V$4:$V$63,'Monthly Model'!$B$4:$B$63,2) -> 52207577 | D22: =SUMIFS('Monthly Model'!$V$4:$V$63,'Monthly Model'!$B$4:$B$63,3) -> 1.2236385e+08 | E22: =SUMIFS('Monthly Model'!$V$4:$V$63,'Monthly Model'!$B$4:$B$63,4) -> 2.2530536e+08 | F22: =SUMIFS('Monthly Model'!$V$4:$V$63,'Monthly Model'!$B$4:$B$63,5) -> 3.5467723e+08
A23: Gross profit | B23: =SUMIFS('Monthly Model'!$W$4:$W$63,'Monthly Model'!$B$4:$B$63,1) -> 18309842 | C23: =SUMIFS('Monthly Model'!$W$4:$W$63,'Monthly Model'!$B$4:$B$63,2) -> 79284752 | D23: =SUMIFS('Monthly Model'!$W$4:$W$63,'Monthly Model'!$B$4:$B$63,3) -> 2.2959434e+08 | E23: =SUMIFS('Monthly Model'!$W$4:$W$63,'Monthly Model'!$B$4:$B$63,4) -> 4.8022549e+08 | F23: =SUMIFS('Monthly Model'!$W$4:$W$63,'Monthly Model'!$B$4:$B$63,5) -> 8.3487549e+08
A24: Gross margin % | B24: =IFERROR(B23/B19,0) -> 0.53384941 | C24: =IFERROR(C23/C19,0) -> 0.60296104 | D24: =IFERROR(D23/D19,0) -> 0.65233413 | E24: =IFERROR(E23/E19,0) -> 0.68065838 | F24: =IFERROR(F23/F19,0) -> 0.70183984
A25: Total opex (excl. agents) | B25: =SUMIFS('Monthly Model'!$AD$4:$AD$63,'Monthly Model'!$B$4:$B$63,1) -> 24300000 | C25: =SUMIFS('Monthly Model'!$AD$4:$AD$63,'Monthly Model'!$B$4:$B$63,2) -> 37200000 | D25: =SUMIFS('Monthly Model'!$AD$4:$AD$63,'Monthly Model'!$B$4:$B$63,3) -> 70200000 | E25: =SUMIFS('Monthly Model'!$AD$4:$AD$63,'Monthly Model'!$B$4:$B$63,4) -> 113100000 | F25: =SUMIFS('Monthly Model'!$AD$4:$AD$63,'Monthly Model'!$B$4:$B$63,5) -> 177900000
A26: EBITDA | B26: =SUMIFS('Monthly Model'!$AE$4:$AE$63,'Monthly Model'!$B$4:$B$63,1) -> -5990158.3 | C26: =SUMIFS('Monthly Model'!$AE$4:$AE$63,'Monthly Model'!$B$4:$B$63,2) -> 42084752 | D26: =SUMIFS('Monthly Model'!$AE$4:$AE$63,'Monthly Model'!$B$4:$B$63,3) -> 1.5939434e+08 | E26: =SUMIFS('Monthly Model'!$AE$4:$AE$63,'Monthly Model'!$B$4:$B$63,4) -> 3.6712549e+08 | F26: =SUMIFS('Monthly Model'!$AE$4:$AE$63,'Monthly Model'!$B$4:$B$63,5) -> 6.5697549e+08
A27: Cash position (end of year) | B27: =INDEX('Monthly Model'!$AF$4:$AF$63,1*12) -> -5990158.3 | C27: =INDEX('Monthly Model'!$AF$4:$AF$63,2*12) -> 36094593 | D27: =INDEX('Monthly Model'!$AF$4:$AF$63,3*12) -> 1.9548893e+08 | E27: =INDEX('Monthly Model'!$AF$4:$AF$63,4*12) -> 5.6261442e+08 | F27: =INDEX('Monthly Model'!$AF$4:$AF$63,5*12) -> 1.2195899e+09 | G27: No fundraise modelled — the trough of this line is what you need to cover.
A29: UNIT ECONOMICS
A30: Revenue per agent (per year) | B30: =IFERROR(B19/B7,0) -> 2947592.4 | C30: =IFERROR(C19/C7,0) -> 4616364 | D30: =IFERROR(D19/D7,0) -> 6986188.5 | E30: =IFERROR(E19/E7,0) -> 9310718.1 | F30: =IFERROR(F19/F7,0) -> 11481835
A31: Closes per agent per month | B31: =IFERROR(B11/B7/12,0) -> 2.5011749 | C31: =IFERROR(C11/C7/12,0) -> 3.2584447 | D31: =IFERROR(D11/D7/12,0) -> 3.6658487 | E31: =IFERROR(E11/E7/12,0) -> 3.8971519 | F31: =IFERROR(F11/F7/12,0) -> 4.0520693 | G31: Watch this one. If it stalls below ~6, the Uyo rental market is too thin to carry the agent bench — and sales has to come forward.
A32: Revenue per closed deal | B32: =IFERROR(B19/B11,0) -> 98206.926 | C32: =IFERROR(C19/C11,0) -> 118061.54 | D32: =IFERROR(D19/D11,0) -> 158812.44 | E32: =IFERROR(E19/E11,0) -> 199092.36 | F32: =IFERROR(F19/F11,0) -> 236131.11
A33: Gross profit per closed deal | B33: =IFERROR(B23/B11,0) -> 52427.71 | C33: =IFERROR(C23/C11,0) -> 71186.51 | D33: =IFERROR(D23/D11,0) -> 103598.77 | E33: =IFERROR(E23/E11,0) -> 135513.89 | F33: =IFERROR(F23/F11,0) -> 165726.22
A35: THE FUNDING QUESTION
A36: Peak funding need (₦) | B36: =-MIN(0,MIN('Monthly Model'!$AF$4:$AF$63)) -> 8689288.6 | G36: The deepest the cash line goes. This is what you must cover before the business self-funds.
A37: Month of deepest cash | B37: =IFERROR(INDEX('Monthly Model'!$A$4:$A$63,MATCH(MIN('Monthly Model'!$AF$4:$AF$63),'Monthly Model'!$AF$4:$AF$63,0)),0) -> 7
A38: First month of positive EBITDA | B38: =IFERROR(INDEX('Monthly Model'!$A$4:$A$63,MATCH(1,INDEX(('Monthly Model'!$AE$4:$AE$63>0)*1,0),0)),0) -> 8 | G38: Monthly operating breakeven.
A39: First month cash turns positive | B39: =IFERROR(INDEX('Monthly Model'!$A$4:$A$63,MATCH(1,INDEX(('Monthly Model'!$AF$4:$AF$63>0)*1,0),0)),0) -> 18 | G39: When cumulative cash clears zero. 0 means it never does under these assumptions.
A41: Gross margin here is after ALL agent cost — commission and stipends both. Opex below it is core team, tech, marketing, office and city launches only.
